Workbook

Sheet report
A1: אורי אשתר | D1: פנדה טק בע"מ | H1: מל"מ
A2: 01.04.2026 - 30.04.2026 | F2: 113 | H2: חוזה עבודה למעט מלמ
A3: תאריך | B3: סוג | C3: כניסה | D3: יציאה | E3: סה"כ שעות | F3: הפסקה | G3: שעות משולמות | H3: תקן | I3: חוסר בתקן | J3: 100% | K3: 125% | L3: שעות עודף | M3: איחור | N3: אירוע | O3: הערה | P3: תוספת
A4: ד - 01 | B4: ערב חג | H4: 00:24 | I4: 00:24 | N4: ערב חג | O4: פסח-2
A5: ה - 02 | B5: חג | N5: חג | O5: פסח-1
A6: ו - 03 | B6: סופ"ש
A7: ש - 04 | B7: סופ"ש
A8: ס.שבועי | H8: 00:24 | I8: 00:24
A9: א - 05 | B9: חול המועד | N9: חול המועד
A10: ב - 06 | B10: חול המועד | N10: חול המועד
A11: ג - 07 | B11: ערב חג | H11: 00:24 | I11: 00:24 | N11: ערב חג | O11: פסח-2
A12: ד - 08 | B12: חג | N12: חג | O12: פסח-2
A13: ה - 09 | B13: יום חול | C13: 07:32 | D13: 16:28 | E13: 08:56 | F13: 00:30 | G13: 08:26 | H13: 08:24 | J13: 08:24 | K13: 00:02 | L13: 00:02 | M13: 00:32
A14: ו - 10 | B14: סופ"ש
A15: ש - 11 | B15: סופ"ש
A16: ס.שבועי | E16: 08:56 | F16: 00:30 | G16: 08:26 | H16: 08:48 | I16: 00:24 | J16: 08:24 | K16: 00:02 | L16: 00:02 | M16: 00:32
A17: א - 12 | B17: יום חול | C17: 07:46 | D17: 17:09 | E17: 09:23 | F17: 00:30 | G17: 08:53 | H17: 08:24 | J17: 08:24 | K17: 00:29 | L17: 00:29 | M17: 00:46
A18: ב - 13 | B18: יום חול | C18: 08:04 | D18: 16:48 | E18: 08:44 | F18: 00:30 | G18: 08:14 | H18: 08:24 | I18: 00:10 | J18: 08:14 | M18: 01:04
A19: ג - 14 | B19: יום חול | C19: 08:21 | D19: 17:26 | E19: 09:05 | F19: 00:30 | G19: 08:35 | H19: 08:24 | J19: 08:24 | K19: 00:11 | L19: 00:11 | M19: 01:21
A20: ד - 15 | B20: יום חול | C20: 10:37 | D20: 17:26 | E20: 06:49 | F20: 00:30 | G20: 06:19 | H20: 08:24 | I20: 02:05 | J20: 06:19 | M20: 03:37
A21: ה - 16 | B21: יום חול | C21: 08:09 | D21: 17:23 | E21: 09:14 | F21: 00:30 | G21: 08:44 | H21: 08:24 | J21: 08:24 | K21: 00:20 | L21: 00:20 | M21: 01:09
A22: ו - 17 | B22: סופ"ש
A23: ש - 18 | B23: סופ"ש
A24: ס.שבועי | E24: 43:15 | F24: 02:30 | G24: 40:45 | H24: 42:00 | I24: 02:15 | J24: 39:45 | K24: 01:00 | L24: 01:00 | M24: 07:57
A25: א - 19 | B25: יום חול | C25: 07:55 | D25: 16:41 | E25: 08:46 | F25: 00:30 | G25: 08:16 | H25: 08:24 | I25: 00:08 | J25: 08:16 | M25: 00:55
A26: ב - 20 | B26: יום חול | C26: 07:57 | D26: 16:09 | E26: 08:12 | F26: 00:30 | G26: 07:42 | H26: 01:24 | J26: 07:42 | L26: 06:18 | M26: 00:57
A27: ג - 21 | B27: ערב חג | H27: 07:24 | I27: 07:24 | N27: ערב חג | O27: זכרון+עצמאות
A28: ד - 22 | B28: חג | N28: חג | O28: זכרון+עצמאות
A29: ה - 23 | B29: יום חול | C29: 08:17 | D29: 17:14 | E29: 08:57 | F29: 00:30 | G29: 08:27 | H29: 08:24 | J29: 08:24 | K29: 00:03 | L29: 00:03 | M29: 01:17
A30: ו - 24 | B30: סופ"ש
A31: ש - 25 | B31: סופ"ש
A32: ס.שבועי | E32: 25:55 | F32: 01:30 | G32: 24:25 | H32: 25:36 | I32: 07:32 | J32: 24:22 | K32: 00:03 | L32: 06:21 | M32: 03:09
A33: א - 26 | B33: יום חול | C33: 08:07 | D33: 17:02 | E33: 08:55 | F33: 00:30 | G33: 08:25 | H33: 08:24 | J33: 08:24 | K33: 00:01 | L33: 00:01 | M33: 01:07
A34: ב - 27 | B34: יום חול | C34: 07:55 | D34: 17:17 | E34: 09:22 | F34: 00:30 | G34: 08:52 | H34: 08:24 | J34: 08:24 | K34: 00:28 | L34: 00:28 | M34: 00:55
A35: ג - 28 | B35: יום חול | C35: 08:12 | D35: 17:37 | E35: 09:25 | F35: 00:30 | G35: 08:55 | H35: 08:24 | J35: 08:24 | K35: 00:31 | L35: 00:31 | M35: 01:12
A36: ד - 29 | B36: יום חול | C36: 08:06 | D36: 17:13 | E36: 09:07 | F36: 00:30 | G36: 08:37 | H36: 08:24 | J36: 08:24 | K36: 00:13 | L36: 00:13 | M36: 01:06
A37: ה - 30 | B37: יום חול | C37: 08:14 | D37: 17:34 | E37: 09:20 | F37: 00:30 | G37: 08:50 | H37: 08:24 | J37: 08:24 | K37: 00:26 | L37: 00:26 | M37: 01:14
A38: חישוב יומי: שעות ודקות | E38: 124:15 | F38: 07:00 | G38: 117:15 | H38: 118:48 | I38: 10:35 | J38: 114:31 | K38: 02:44 | L38: 09:02 | M38: 17:12
A39: סיכום חודשי: שעות ודקות | E39: 124:15 | F39: 07:00 | G39: 117:15 | H39: 118:48 | I39: 01:33 | J39: 114:31 | K39: 02:44 | L39: 09:02 | M39: 17:12
A40: סיכום חודשי: עשרוני | E40: 124.25 | F40: 7 | G40: 117.25 | H40: 118.8 | I40: 1.55 | J40: 114.51 | K40: 2.73 | L40: 9.03 | M40: 17.2
...

Sheet Em_Index
A1: מספר עובד | B1: מספר זהות | C1: שם משפחה | D1: שם פרטי
A2: 1 | B2: 28718427 | C2: זהר | D2: בנימין
A3: 2 | B3: 31942915 | C3: לייבנזון | D3: אבישי
A4: 7 | B4: 69304962 | C4: ראש | D4: חיים
A5: 8 | B5: 59659250 | C5: אחדות | D5: דוד
A6: 11 | B6: 55308241 | C6: דביש | D6: לוי
A7: 22 | B7: 22996672 | C7: רחמנוב | D7: חגי אפרים
A8: 34 | B8: 22201347 | C8: שלמה | D8: יורם
A9: 41 | B9: 206092371 | C9: אולשנסקי | D9: דניאל
A10: 54 | B10: 28452837 | C10: לוי | D10: דוד
A11: 60 | B11: 24588790 | C11: בנג'יו | D11: אברהם
A12: 62 | B12: 308280510 | C12: לוי | D12: דור
A13: 64 | B13: 315536524 | C13: חנגל | D13: צחי
... A52: 127 | B52: 31743420 | C52: זמן | D52: שרון

Sheet נייר עבודה
A1: נייר עבודה - דינמי (נוסחאות מ-report)
A3: מס' עובד | B3: שם עובד | C3: ימי נוכחות | D3: ימים משולמים | E3: חופשה לחיוב | F3: ימי מחלה | G3: ימי מילואים | H3: סה"כ שעות (משולמות) | I3: שעות 100% | J3: שעות 125% | K3: שעות 150% | L3: שעות עבודה במילואים | M3: מחלה לקיזוז | N3: חל"ת | O3: היעדרות | P3: חג | Q3: ע.חג | R3: חוה"מ | S3: ת.עבודה | T3: חופש קיים | U3: צפוי | V3: פער
A4: 7 | B4: חיים ראש | C4: =report!C514 -> 12 | D4: =report!C515 -> 21 | E4: =IFERROR(INDEX(report!$K$513:$K$527,MATCH("חופשה לחיוב",report!$I$513:$I$527,0)),0) -> 4.5 | F4: =IFERROR(INDEX(report!$K$513:$K$527,MATCH("מחלה",report!$I$513:$I$527,0)),0) -> 0 | G4: =IFERROR(INDEX(report!$K$513:$K$527,MATCH("מילואים",report!$I$513:$I$527,0)),0) -> 0 | H4: =report!G511 -> 115.4 | I4: =report!J511 -> 100.05 | J4: =report!K511 -> 13.53 | K4: =report!L511 -> 1.81 | L4: =report!C523 -> 0 | M4: =IFERROR(INDEX(report!$K$513:$K$527,MATCH("מחלה לקיזוז",report!$I$513:$I$527,0)),0) -> 0 | N4: =IFERROR(INDEX(report!$K$513:$K$527,MATCH("חל""ת",report!$I$513:$I$527,0)),0) -> 0 | O4: =IFERROR(INDEX(report!$K$513:$K$527,MATCH("היעדרות",report!$I$513:$I$527,0)),0) -> 0 | P4: =IFERROR(INDEX(report!$K$513:$K$527,MATCH("חג",report!$I$513:$I$527,0)),0) -> 3 | Q4: =IFERROR(INDEX(report!$K$513:$K$527,MATCH("ערב חג",report!$I$513:$I$527,0)),0) -> 3 | R4: =IFERROR(INDEX(report!$K$513:$K$527,MATCH("חול המועד",report!$I$513:$I$527,0)),0) -> 2 | S4: =IFERROR(INDEX(report!$K$513:$K$527,MATCH("תאונת עבודה",report!$I$513:$I$527,0)),0) -> 0 | T4: =IFERROR(INDEX(report!$K$513:$K$527,MATCH("חופש",report!$I$513:$I$527,0)),0) -> 2 | U4: =22-M4-N4-O4 -> 22 | V4: =D4-U4 -> -1
A5: 8 | B5: דוד אחדות | C5: =report!C358 -> 12 | D5: =report!C359 -> 22 | E5: =IFERROR(INDEX(report!$K$357:$K$371,MATCH("חופשה לחיוב",report!$I$357:$I$371,0)),0) -> 5.5 | F5: =IFERROR(INDEX(report!$K$357:$K$371,MATCH("מחלה",report!$I$357:$I$371,0)),0) -> 0 | G5: =IFERROR(INDEX(report!$K$357:$K$371,MATCH("מילואים",report!$I$357:$I$371,0)),0) -> 0 | H5: =report!G355 -> 117.65 | I5: =report!J355 -> 100.58 | J5: =report!K355 -> 16.68 | K5: =report!L355 -> 0.38 | L5: =report!C367 -> 0 | M5: =IFERROR(INDEX(report!$K$357:$K$371,MATCH("מחלה לקיזוז",report!$I$357:$I$371,0)),0) -> 0 | N5: =IFERROR(INDEX(report!$K$357:$K$371,MATCH("חל""ת",report!$I$357:$I$371,0)),0) -> 0 | O5: =IFERROR(INDEX(report!$K$357:$K$371,MATCH("היעדרות",report!$I$357:$I$371,0)),0) -> 0 | P5: =IFERROR(INDEX(report!$K$357:$K$371,MATCH("חג",report!$I$357:$I$371,0)),0) -> 3 | Q5: =IFERROR(INDEX(report!$K$357:$K$371,MATCH("ערב חג",report!$I$357:$I$371,0)),0) -> 3 | R5: =IFERROR(INDEX(report!$K$357:$K$371,MATCH("חול המועד",report!$I$357:$I$371,0)),0) -> 2 | S5: =IFERROR(INDEX(report!$K$357:$K$371,MATCH("תאונת עבודה",report!$I$357:$I$371,0)),0) -> 0 | T5: =IFERROR(INDEX(report!$K$357:$K$371,MATCH("חופש",report!$I$357:$I$371,0)),0) -> 2 | U5: =22-M5-N5-O5 -> 22 | V5: =D5-U5 -> 0
A6: 11 | B6: לוי דביש | C6: =report!C566 -> 12 | D6: =report!C567 -> 20 | E6: =IFERROR(INDEX(report!$K$565:$K$579,MATCH("חופשה לחיוב",report!$I$565:$I$579,0)),0) -> 1.5 | F6: =IFERROR(INDEX(report!$K$565:$K$579,MATCH("מחלה",report!$I$565:$I$579,0)),0) -> 0 | G6: =IFERROR(INDEX(report!$K$565:$K$579,MATCH("מילואים",report!$I$565:$I$579,0)),0) -> 0 | H6: =report!G563 -> 76.98 | I6: =report!J563 -> 76.98 | J6: 0 | K6: 0 | L6: =report!C575 -> 0 | M6: =IFERROR(INDEX(report!$K$565:$K$579,MATCH("מחלה לקיזוז",report!$I$565:$I$579,0)),0) -> 0 | N6: =IFERROR(INDEX(report!$K$565:$K$579,MATCH("חל""ת",report!$I$565:$I$579,0)),0) -> 0 | O6: =IFERROR(INDEX(report!$K$565:$K$579,MATCH("היעדרות",report!$I$565:$I$579,0)),0) -> 2 | P6: =IFERROR(INDEX(report!$K$565:$K$579,MATCH("חג",report!$I$565:$I$579,0)),0) -> 3 | Q6: =IFERROR(INDEX(report!$K$565:$K$579,MATCH("ערב חג",report!$I$565:$I$579,0)),0) -> 3 | R6: =IFERROR(INDEX(report!$K$565:$K$579,MATCH("חול המועד",report!$I$565:$I$579,0)),0) -> 2 | S6: =IFERROR(INDEX(report!$K$565:$K$579,MATCH("תאונת עבודה",report!$I$565:$I$579,0)),0) -> 0 | T6: =IFERROR(INDEX(report!$K$565:$K$579,MATCH("חופש",report!$I$565:$I$579,0)),0) -> 0 | U6: =22-M6-N6-O6 -> 20 | V6: =D6-U6 -> 0
A7: 22 | B7: אפרים רחמנוב | C7: =report!C201 -> 14 | D7: =report!C202 -> 22 | E7: =IFERROR(INDEX(report!$K$200:$K$214,MATCH("חופשה לחיוב",report!$I$200:$I$214,0)),0) -> 3.5 | F7: =IFERROR(INDEX(report!$K$200:$K$214,MATCH("מחלה",report!$I$200:$I$214,0)),0) -> 0 | G7: =IFERROR(INDEX(report!$K$200:$K$214,MATCH("מילואים",report!$I$200:$I$214,0)),0) -> 0 | H7: =report!G198 -> 129.65 | I7: =report!J198 -> 115.7 | J7: =report!K198 -> 13.5 | K7: =report!L198 -> 0.45 | L7: =report!C210 -> 0 | M7: =IFERROR(INDEX(report!$K$200:$K$214,MATCH("מחלה לקיזוז",report!$I$200:$I$214,0)),0) -> 0 | N7: =IFERROR(INDEX(report!$K$200:$K$214,MATCH("חל""ת",report!$I$200:$I$214,0)),0) -> 0 | O7: =IFERROR(INDEX(report!$K$200:$K$214,MATCH("היעדרות",report!$I$200:$I$214,0)),0) -> 0 | P7: =IFERROR(INDEX(report!$K$200:$K$214,MATCH("חג",report!$I$200:$I$214,0)),0) -> 3 | Q7: =IFERROR(INDEX(report!$K$200:$K$214,MATCH("ערב חג",report!$I$200:$I$214,0)),0) -> 3 | R7: =IFERROR(INDEX(report!$K$200:$K$214,MATCH("חול המועד",report!$I$200:$I$214,0)),0) -> 0 | S7: =IFERROR(INDEX(report!$K$200:$K$214,MATCH("תאונת עבודה",report!$I$200:$I$214,0)),0) -> 0 | T7: =IFERROR(INDEX(report!$K$200:$K$214,MATCH("חופש",report!$I$200:$I$214,0)),0) -> 2 | U7: =22-M7-N7-O7 -> 22 | V7: =D7-U7 -> 0
A8: 54 | B8: דוד לוי | C8: =report!C1142 -> 10 | D8: =report!C1143 -> 18 | E8: =IFERROR(INDEX(report!$K$1141:$K$1155,MATCH("חופשה לחיוב",report!$I$1141:$I$1155,0)),0) -> 4 | F8: =IFERROR(INDEX(report!$K$1141:$K$1155,MATCH("מחלה",report!$I$1141:$I$1155,0)),0) -> 4 | G8: =IFERROR(INDEX(report!$K$1141:$K$1155,MATCH("מילואים",report!$I$1141:$I$1155,0)),0) -> 0 | H8: =report!G1139 -> 69.86 | I8: =report!J1139 -> 67.13 | J8: =report!K1139 -> 2.38 | K8: =report!L1139 -> 0.35 | L8: =report!C1151 -> 0 | M8: =IFERROR(INDEX(report!$K$1141:$K$1155,MATCH("מחלה לקיזוז",report!$I$1141:$I$1155,0)),0) -> 2 | N8: =IFERROR(INDEX(report!$K$1141:$K$1155,MATCH("חל""ת",report!$I$1141:$I$1155,0)),0) -> 2 | O8: =IFERROR(INDEX(report!$K$1141:$K$1155,MATCH("היעדרות",report!$I$1141:$I$1155,0)),0) -> 0 | P8: =IFERROR(INDEX(report!$K$1141:$K$1155,MATCH("חג",report!$I$1141:$I$1155,0)),0) -> 3 | Q8: =IFERROR(INDEX(report!$K$1141:$K$1155,MATCH("ערב חג",report!$I$1141:$I$1155,0)),0) -> 2 | R8: =IFERROR(INDEX(report!$K$1141:$K$1155,MATCH("חול המועד",report!$I$1141:$I$1155,0)),0) -> 2 | S8: =IFERROR(INDEX(report!$K$1141:$K$1155,MATCH("תאונת עבודה",report!$I$1141:$I$1155,0)),0) -> 0 | T8: =IFERROR(INDEX(report!$K$1141:$K$1155,MATCH("חופש",report!$I$1141:$I$1155,0)),0) -> 1 | U8: =22-M8-N8-O8 -> 18 | V8: =D8-U8 -> 0
A9: 60 | B9: אבי בנג'ו | C9: =report!C1612 -> 15 | D9: =report!C1613 -> 22 | E9: =IFERROR(INDEX(report!$K$1611:$K$1625,MATCH("חופשה לחיוב",report!$I$1611:$I$1625,0)),0) -> 3 | F9: =IFERROR(INDEX(report!$K$1611:$K$1625,MATCH("מחלה",report!$I$1611:$I$1625,0)),0) -> 0 | G9: =IFERROR(INDEX(report!$K$1611:$K$1625,MATCH("מילואים",report!$I$1611:$I$1625,0)),0) -> 0 | H9: =report!G1609 -> 135.11 | I9: =report!J1609 -> 125 | J9: =report!K1609 -> 10.11 | K9: 0 | L9: =report!C1621 -> 0 | M9: =IFERROR(INDEX(report!$K$1611:$K$1625,MATCH("מחלה לקיזוז",report!$I$1611:$I$1625,0)),0) -> 0 | N9: =IFERROR(INDEX(report!$K$1611:$K$1625,MATCH("חל""ת",report!$I$1611:$I$1625,0)),0) -> 0 | O9: =IFERROR(INDEX(report!$K$1611:$K$1625,MATCH("היעדרות",report!$I$1611:$I$1625,0)),0) -> 0 | P9: =IFERROR(INDEX(report!$K$1611:$K$1625,MATCH("חג",report!$I$1611:$I$1625,0)),0) -> 3 | Q9: =IFERROR(INDEX(report!$K$1611:$K$1625,MATCH("ערב חג",report!$I$1611:$I$1625,0)),0) -> 2 | R9: =IFERROR(INDEX(report!$K$1611:$K$1625,MATCH("חול המועד",report!$I$1611:$I$1625,0)),0) -> 0 | S9: =IFERROR(INDEX(report!$K$1611:$K$1625,MATCH("תאונת עבודה",report!$I$1611:$I$1625,0)),0) -> 0 | T9: =IFERROR(INDEX(report!$K$1611:$K$1625,MATCH("חופש",report!$I$1611:$I$1625,0)),0) -> 2 | U9: =22-M9-N9-O9 -> 22 | V9: =D9-U9 -> 0
A10: 62 | B10: לוי דור | C10: =report!C1924 -> 3 | D10: =report!C1925 -> 22 | E10: =IFERROR(INDEX(report!$K$1923:$K$1937,MATCH("חופשה לחיוב",report!$I$1923:$I$1937,0)),0) -> 5 | F10: =IFERROR(INDEX(report!$K$1923:$K$1937,MATCH("מחלה",report!$I$1923:$I$1937,0)),0) -> 0 | G10: =IFERROR(INDEX(report!$K$1923:$K$1937,MATCH("מילואים",report!$I$1923:$I$1937,0)),0) -> 15 | H10: =report!G1921 -> 25.75 | I10: =report!J1921 -> 24.2 | J10: =report!K1921 -> 1.55 | K10: 0 | L10: =report!C1933 -> 8.4 | M10: =IFERROR(INDEX(report!$K$1923:$K$1937,MATCH("מחלה לקיזוז",report!$I$1923:$I$1937,0)),0) -> 0 | N10: =IFERROR(INDEX(report!$K$1923:$K$1937,MATCH("חל""ת",report!$I$1923:$I$1937,0)),0) -> 0 | O10: =IFERROR(INDEX(report!$K$1923:$K$1937,MATCH("היעדרות",report!$I$1923:$I$1937,0)),0) -> 0 | P10: =IFERROR(INDEX(report!$K$1923:$K$1937,MATCH("חג",report!$I$1923:$I$1937,0)),0) -> 3 | Q10: =IFERROR(INDEX(report!$K$1923:$K$1937,MATCH("ערב חג",report!$I$1923:$I$1937,0)),0) -> 2 | R10: =IFERROR(INDEX(report!$K$1923:$K$1937,MATCH("חול המועד",report!$I$1923:$I$1937,0)),0) -> 2 | S10: =IFERROR(INDEX(report!$K$1923:$K$1937,MATCH("תאונת עבודה",report!$I$1923:$I$1937,0)),0) -> 0 | T10: =IFERROR(INDEX(report!$K$1923:$K$1937,MATCH("חופש",report!$I$1923:$I$1937,0)),0) -> 2 | U10: =22-M10-N10-O10 -> 22 | V10: =D10-U10 -> 0
A11: 64 | B11: צחי חנגל | C11: =report!C2188 -> 12 | D11: =report!C2189 -> 20.5 | E11: =IFERROR(INDEX(report!$K$2187:$K$2201,MATCH("חופשה לחיוב",report!$I$2187:$I$2201,0)),0) -> 3 | F11: =IFERROR(INDEX(report!$K$2187:$K$2201,MATCH("מחלה",report!$I$2187:$I$2201,0)),0) -> 2 | G11: =IFERROR(INDEX(report!$K$2187:$K$2201,MATCH("מילואים",report!$I$2187:$I$2201,0)),0) -> 1 | H11: =report!G2185 -> 104.36 | I11: =report!J2185 -> 99.8 | J11: =report!K2185 -> 4.56 | K11: 0 | L11: =report!C2197 -> 0 | M11: =IFERROR(INDEX(report!$K$2187:$K$2201,MATCH("מחלה לקיזוז",report!$I$2187:$I$2201,0)),0) -> 1.5 | N11: =IFERROR(INDEX(report!$K$2187:$K$2201,MATCH("חל""ת",report!$I$2187:$I$2201,0)),0) -> 0 | O11: =IFERROR(INDEX(report!$K$2187:$K$2201,MATCH("היעדרות",report!$I$2187:$I$2201,0)),0) -> 0 | P11: =IFERROR(INDEX(report!$K$2187:$K$2201,MATCH("חג",report!$I$2187:$I$2201,0)),0) -> 3 | Q11: =IFERROR(INDEX(report!$K$2187:$K$2201,MATCH("ערב חג",report!$I$2187:$I$2201,0)),0) -> 2 | R11: =IFERROR(INDEX(report!$K$2187:$K$2201,MATCH("חול המועד",report!$I$2187:$I$2201,0)),0) -> 2 | S11: =IFERROR(INDEX(report!$K$2187:$K$2201,MATCH("תאונת עבודה",report!$I$2187:$I$2201,0)),0) -> 0 | T11: =IFERROR(INDEX(report!$K$2187:$K$2201,MATCH("חופש",report!$I$2187:$I$2201,0)),0) -> 0 | U11: =22-M11-N11-O11 -> 20.5 | V11: =D11-U11 -> 0
A12: 65 | B12: שלמה לסנר | C12: =report!C775 -> 18 | D12: =report!C776 -> 22 | E12: =IFERROR(INDEX(report!$K$774:$K$788,MATCH("חופשה לחיוב",report!$I$774:$I$788,0)),0) -> 0.5 | F12: =IFERROR(INDEX(report!$K$774:$K$788,MATCH("מחלה",report!$I$774:$I$788,0)),0) -> 0 | G12: =IFERROR(INDEX(report!$K$774:$K$788,MATCH("מילואים",report!$I$774:$I$788,0)),0) -> 0 | H12: =report!G772 -> 181.98 | I12: =report!J772 -> 144.46 | J12: =report!K772 -> 27.83 | K12: =report!L772 -> 9.68 | L12: =report!C784 -> 0 | M12: =IFERROR(INDEX(report!$K$774:$K$788,MATCH("מחלה לקיזוז",report!$I$774:$I$788,0)),0) -> 0 | N12: =IFERROR(INDEX(report!$K$774:$K$788,MATCH("חל""ת",report!$I$774:$I$788,0)),0) -> 0 | O12: =IFERROR(INDEX(report!$K$774:$K$788,MATCH("היעדרות",report!$I$774:$I$788,0)),0) -> 0 | P12: =IFERROR(INDEX(report!$K$774:$K$788,MATCH("חג",report!$I$774:$I$788,0)),0) -> 3 | Q12: =IFERROR(INDEX(report!$K$774:$K$788,MATCH("ערב חג",report!$I$774:$I$788,0)),0) -> 1 | R12: =IFERROR(INDEX(report!$K$774:$K$788,MATCH("חול המועד",report!$I$774:$I$788,0)),0) -> 2 | S12: =IFERROR(INDEX(report!$K$774:$K$788,MATCH("תאונת עבודה",report!$I$774:$I$788,0)),0) -> 0 | T12: =IFERROR(INDEX(report!$K$774:$K$788,MATCH("חופש",report!$I$774:$I$788,0)),0) -> 0 | U12: =22-M12-N12-O12 -> 22 | V12: =D12-U12 -> 0
A13: 66 | B13: מיכאל רפאל | C13: =report!C1980 -> 17 | D13: =report!C1981 -> 22 | E13: =IFERROR(INDEX(report!$K$1979:$K$1993,MATCH("חופשה לחיוב",report!$I$1979:$I$1993,0)),0) -> 2 | F13: =IFERROR(INDEX(report!$K$1979:$K$1993,MATCH("מחלה",report!$I$1979:$I$1993,0)),0) -> 0 | G13: =IFERROR(INDEX(report!$K$1979:$K$1993,MATCH("מילואים",report!$I$1979:$I$1993,0)),0) -> 0 | H13: =report!G1977 -> 140.53 | I13: =report!J1977 -> 129.6 | J13: =report!K1977 -> 10.93 | K13: 0 | L13: =report!C1989 -> 0 | M13: =IFERROR(INDEX(report!$K$1979:$K$1993,MATCH("מחלה לקיזוז",report!$I$1979:$I$1993,0)),0) -> 0 | N13: =IFERROR(INDEX(report!$K$1979:$K$1993,MATCH("חל""ת",report!$I$1979:$I$1993,0)),0) -> 0 | O13: =IFERROR(INDEX(report!$K$1979:$K$1993,MATCH("היעדרות",report!$I$1979:$I$1993,0)),0) -> 0 | P13: =IFERROR(INDEX(report!$K$1979:$K$1993,MATCH("חג",report!$I$1979:$I$1993,0)),0) -> 3 | Q13: =IFERROR(INDEX(report!$K$1979:$K$1993,MATCH("ערב חג",report!$I$1979:$I$1993,0)),0) -> 0 | R13: =IFERROR(INDEX(report!$K$1979:$K$1993,MATCH("חול המועד",report!$I$1979:$I$1993,0)),0) -> 2 | S13: =IFERROR(INDEX(report!$K$1979:$K$1993,MATCH("תאונת עבודה",report!$I$1979:$I$1993,0)),0) -> 0 | T13: =IFERROR(INDEX(report!$K$1979:$K$1993,MATCH("חופש",report!$I$1979:$I$1993,0)),0) -> 0 | U13: =22-M13-N13-O13 -> 22 | V13: =D13-U13 -> 0
A14: 75 | B14: אייל מלח | C14: =report!C1716 -> 11 | D14: =report!C1717 -> 22 | E14: =IFERROR(INDEX(report!$K$1715:$K$1729,MATCH("חופשה לחיוב",report!$I$1715:$I$1729,0)),0) -> 0 | F14: =IFERROR(INDEX(report!$K$1715:$K$1729,MATCH("מחלה",report!$I$1715:$I$1729,0)),0) -> 0 | G14: =IFERROR(INDEX(report!$K$1715:$K$1729,MATCH("מילואים",report!$I$1715:$I$1729,0)),0) -> 30 | H14: =report!G1713 -> 97.2 | I14: =report!J1713 -> 92.4 | J14: =report!K1713 -> 4.8 | K14: 0 | L14: =report!C1725 -> 92.4 | M14: =IFERROR(INDEX(report!$K$1715:$K$1729,MATCH("מחלה לקיזוז",report!$I$1715:$I$1729,0)),0) -> 0 | N14: =IFERROR(INDEX(report!$K$1715:$K$1729,MATCH("חל""ת",report!$I$1715:$I$1729,0)),0) -> 0 | O14: =IFERROR(INDEX(report!$K$1715:$K$1729,MATCH("היעדרות",report!$I$1715:$I$1729,0)),0) -> 0 | P14: =IFERROR(INDEX(report!$K$1715:$K$1729,MATCH("חג",report!$I$1715:$I$1729,0)),0) -> 0 | Q14: =IFERROR(INDEX(report!$K$1715:$K$1729,MATCH("ערב חג",report!$I$1715:$I$1729,0)),0) -> 0 | R14: =IFERROR(INDEX(report!$K$1715:$K$1729,MATCH("חול המועד",report!$I$1715:$I$1729,0)),0) -> 0 | S14: =IFERROR(INDEX(report!$K$1715:$K$1729,MATCH("תאונת עבודה",report!$I$1715:$I$1729,0)),0) -> 0 | T14: =IFERROR(INDEX(report!$K$1715:$K$1729,MATCH("חופש",report!$I$1715:$I$1729,0)),0) -> 0 | U14: =22-M14-N14-O14 -> 22 | V14: =D14-U14 -> 0
A15: 76 | B15: מנפרד מרקוביץ' | C15: =report!C2032 -> 8 | D15: =report!C2033 -> 22 | E15: =IFERROR(INDEX(report!$K$2031:$K$2045,MATCH("חופשה לחיוב",report!$I$2031:$I$2045,0)),0) -> 0 | F15: =IFERROR(INDEX(report!$K$2031:$K$2045,MATCH("מחלה",report!$I$2031:$I$2045,0)),0) -> 0 | G15: =IFERROR(INDEX(report!$K$2031:$K$2045,MATCH("מילואים",report!$I$2031:$I$2045,0)),0) -> 23 | H15: =report!G2029 -> 78.48 | I15: =report!J2029 -> 64.58 | J15: =report!K2029 -> 12.41 | K15: =report!L2029 -> 1.48 | L15: =report!C2041 -> 33.6 | M15: =IFERROR(INDEX(report!$K$2031:$K$2045,MATCH("מחלה לקיזוז",report!$I$2031:$I$2045,0)),0) -> 0 | N15: =IFERROR(INDEX(report!$K$2031:$K$2045,MATCH("חל""ת",report!$I$2031:$I$2045,0)),0) -> 0 | O15: =IFERROR(INDEX(report!$K$2031:$K$2045,MATCH("היעדרות",report!$I$2031:$I$2045,0)),0) -> 0 | P15: =IFERROR(INDEX(report!$K$2031:$K$2045,MATCH("חג",report!$I$2031:$I$2045,0)),0) -> 3 | Q15: =IFERROR(INDEX(report!$K$2031:$K$2045,MATCH("ערב חג",report!$I$2031:$I$2045,0)),0) -> 0 | R15: =IFERROR(INDEX(report!$K$2031:$K$2045,MATCH("חול המועד",report!$I$2031:$I$2045,0)),0) -> 0 | S15: =IFERROR(INDEX(report!$K$2031:$K$2045,MATCH("תאונת עבודה",report!$I$2031:$I$2045,0)),0) -> 0 | T15: =IFERROR(INDEX(report!$K$2031:$K$2045,MATCH("חופש",report!$I$2031:$I$2045,0)),0) -> 0 | U15: =22-M15-N15-O15 -> 22 | V15: =D15-U15 -> 0
A16: 78 | B16: אורן סרויה | C16: =report!C1090 -> 16 | D16: =report!C1091 -> 22 | E16: =IFERROR(INDEX(report!$K$1089:$K$1103,MATCH("חופשה לחיוב",report!$I$1089:$I$1103,0)),0) -> 2 | F16: =IFERROR(INDEX(report!$K$1089:$K$1103,MATCH("מחלה",report!$I$1089:$I$1103,0)),0) -> 0 | G16: =IFERROR(INDEX(report!$K$1089:$K$1103,MATCH("מילואים",report!$I$1089:$I$1103,0)),0) -> 0 | H16: =report!G1087 -> 151.86 | I16: =report!J1087 -> 133.4 | J16: =report!K1087 -> 17.15 | K16: =report!L1087 -> 1.31 | L16: =report!C1099 -> 0 | M16: =IFERROR(INDEX(report!$K$1089:$K$1103,MATCH("מחלה לקיזוז",report!$I$1089:$I$1103,0)),0) -> 0 | N16: =IFERROR(INDEX(report!$K$1089:$K$1103,MATCH("חל""ת",report!$I$1089:$I$1103,0)),0) -> 0 | O16: =IFERROR(INDEX(report!$K$1089:$K$1103,MATCH("היעדרות",report!$I$1089:$I$1103,0)),0) -> 0 | P16: =IFERROR(INDEX(report!$K$1089:$K$1103,MATCH("חג",report!$I$1089:$I$1103,0)),0) -> 3 | Q16: =IFERROR(INDEX(report!$K$1089:$K$1103,MATCH("ערב חג",report!$I$1089:$I$1103,0)),0) -> 2 | R16: =IFERROR(INDEX(report!$K$1089:$K$1103,MATCH("חול המועד",report!$I$1089:$I$1103,0)),0) -> 2 | S16: =IFERROR(INDEX(report!$K$1089:$K$1103,MATCH("תאונת עבודה",report!$I$1089:$I$1103,0)),0) -> 0 | T16: =IFERROR(INDEX(report!$K$1089:$K$1103,MATCH("חופש",report!$I$1089:$I$1103,0)),0) -> 1 | U16: =22-M16-N16-O16 -> 22 | V16: =D16-U16 -> 0
A17: 86 | B17: נתן פרדר | C17: =report!C1508 -> 14 | D17: =report!C1509 -> 22 | E17: =IFERROR(INDEX(report!$K$1507:$K$1521,MATCH("חופשה לחיוב",report!$I$1507:$I$1521,0)),0) -> 0 | F17: =IFERROR(INDEX(report!$K$1507:$K$1521,MATCH("מחלה",report!$I$1507:$I$1521,0)),0) -> 0 | G17: =IFERROR(INDEX(report!$K$1507:$K$1521,MATCH("מילואים",report!$I$1507:$I$1521,0)),0) -> 23 | H17: =report!G1505 -> 128.4 | I17: =report!J1505 -> 112.11 | J17: =report!K1505 -> 15.51 | K17: =report!L1505 -> 0.76 | L17: =report!C1517 -> 78.516667 | M17: =IFERROR(INDEX(report!$K$1507:$K$1521,MATCH("מחלה לקיזוז",report!$I$1507:$I$1521,0)),0) -> 0 | N17: =IFERROR(INDEX(report!$K$1507:$K$1521,MATCH("חל""ת",report!$I$1507:$I$1521,0)),0) -> 0 | O17: =IFERROR(INDEX(report!$K$1507:$K$1521,MATCH("היעדרות",report!$I$1507:$I$1521,0)),0) -> 0 | P17: =IFERROR(INDEX(report!$K$1507:$K$1521,MATCH("חג",report!$I$1507:$I$1521,0)),0) -> 3 | Q17: =IFERROR(INDEX(report!$K$1507:$K$1521,MATCH("ערב חג",report!$I$1507:$I$1521,0)),0) -> 0 | R17: =IFERROR(INDEX(report!$K$1507:$K$1521,MATCH("חול המועד",report!$I$1507:$I$1521,0)),0) -> 0 | S17: =IFERROR(INDEX(report!$K$1507:$K$1521,MATCH("תאונת עבודה",report!$I$1507:$I$1521,0)),0) -> 0 | T17: =IFERROR(INDEX(report!$K$1507:$K$1521,MATCH("חופש",report!$I$1507:$I$1521,0)),0) -> 0 | U17: =22-M17-N17-O17 -> 22 | V17: =D17-U17 -> 0
A18: 87 | B18: רום יחיא | C18: =report!C1560 -> 6 | D18: =report!C1561 -> 7 | E18: =IFERROR(INDEX(report!$K$1559:$K$1573,MATCH("חופשה לחיוב",report!$I$1559:$I$1573,0)),0) -> 0 | F18: =IFERROR(INDEX(report!$K$1559:$K$1573,MATCH("מחלה",report!$I$1559:$I$1573,0)),0) -> 0 | G18: =IFERROR(INDEX(report!$K$1559:$K$1573,MATCH("מילואים",report!$I$1559:$I$1573,0)),0) -> 0 | H18: =report!G1557 -> 38.95 | I18: =report!J1557 -> 38.95 | J18: 0 | K18: 0 | L18: =report!C1569 -> 0 | M18: =IFERROR(INDEX(report!$K$1559:$K$1573,MATCH("מחלה לקיזוז",report!$I$1559:$I$1573,0)),0) -> 0 | N18: =IFERROR(INDEX(report!$K$1559:$K$1573,MATCH("חל""ת",report!$I$1559:$I$1573,0)),0) -> 15 | O18: =IFERROR(INDEX(report!$K$1559:$K$1573,MATCH("היעדרות",report!$I$1559:$I$1573,0)),0) -> 0 | P18: =IFERROR(INDEX(report!$K$1559:$K$1573,MATCH("חג",report!$I$1559:$I$1573,0)),0) -> 1 | Q18: =IFERROR(INDEX(report!$K$1559:$K$1573,MATCH("ערב חג",report!$I$1559:$I$1573,0)),0) -> 0 | R18: =IFERROR(INDEX(report!$K$1559:$K$1573,MATCH("חול המועד",report!$I$1559:$I$1573,0)),0) -> 0 | S18: =IFERROR(INDEX(report!$K$1559:$K$1573,MATCH("תאונת עבודה",report!$I$1559:$I$1573,0)),0) -> 0 | T18: =IFERROR(INDEX(report!$K$1559:$K$1573,MATCH("חופש",report!$I$1559:$I$1573,0)),0) -> 0 | U18: =22-M18-N18-O18 -> 7 | V18: =D18-U18 -> 0
A19: 92 | B19: לאון שמייב | C19: =report!C1403 -> 14 | D19: =report!C1404 -> 22 | E19: =IFERROR(INDEX(report!$K$1402:$K$1416,MATCH("חופשה לחיוב",report!$I$1402:$I$1416,0)),0) -> 1 | F19: =IFERROR(INDEX(report!$K$1402:$K$1416,MATCH("מחלה",report!$I$1402:$I$1416,0)),0) -> 0 | G19: =IFERROR(INDEX(report!$K$1402:$K$1416,MATCH("מילואים",report!$I$1402:$I$1416,0)),0) -> 3 | H19: =report!G1400 -> 118 | I19: =report!J1400 -> 112.95 | J19: =report!K1400 -> 5.05 | K19: 0 | L19: =report!C1412 -> 0 | M19: =IFERROR(INDEX(report!$K$1402:$K$1416,MATCH("מחלה לקיזוז",report!$I$1402:$I$1416,0)),0) -> 0 | N19: =IFERROR(INDEX(report!$K$1402:$K$1416,MATCH("חל""ת",report!$I$1402:$I$1416,0)),0) -> 0 | O19: =IFERROR(INDEX(report!$K$1402:$K$1416,MATCH("היעדרות",report!$I$1402:$I$1416,0)),0) -> 0 | P19: =IFERROR(INDEX(report!$K$1402:$K$1416,MATCH("חג",report!$I$1402:$I$1416,0)),0) -> 3 | Q19: =IFERROR(INDEX(report!$K$1402:$K$1416,MATCH("ערב חג",report!$I$1402:$I$1416,0)),0) -> 2 | R19: =IFERROR(INDEX(report!$K$1402:$K$1416,MATCH("חול המועד",report!$I$1402:$I$1416,0)),0) -> 0 | S19: =IFERROR(INDEX(report!$K$1402:$K$1416,MATCH("תאונת עבודה",report!$I$1402:$I$1416,0)),0) -> 0 | T19: =IFERROR(INDEX(report!$K$1402:$K$1416,MATCH("חופש",report!$I$1402:$I$1416,0)),0) -> 0 | U19: =22-M19-N19-O19 -> 22 | V19: =D19-U19 -> 0
A20: 93 | B20: יום טוב מוסארי | C20: =report!C1351 -> 17 | D20: =report!C1352 -> 22 | E20: =IFERROR(INDEX(report!$K$1350:$K$1364,MATCH("חופשה לחיוב",report!$I$1350:$I$1364,0)),0) -> 0 | F20: =IFERROR(INDEX(report!$K$1350:$K$1364,MATCH("מחלה",report!$I$1350:$I$1364,0)),0) -> 0 | G20: =IFERROR(INDEX(report!$K$1350:$K$1364,MATCH("מילואים",report!$I$1350:$I$1364,0)),0) -> 14 | H20: =report!G1348 -> 147.38 | I20: =report!J1348 -> 136.48 | J20: =report!K1348 -> 10.63 | K20: =report!L1348 -> 0.26 | L20: =report!C1360 -> 46.65 | M20: =IFERROR(INDEX(report!$K$1350:$K$1364,MATCH("מחלה לקיזוז",report!$I$1350:$I$1364,0)),0) -> 0 | N20: =IFERROR(INDEX(report!$K$1350:$K$1364,MATCH("חל""ת",report!$I$1350:$I$1364,0)),0) -> 0 | O20: =IFERROR(INDEX(report!$K$1350:$K$1364,MATCH("היעדרות",report!$I$1350:$I$1364,0)),0) -> 0 | P20: =IFERROR(INDEX(report!$K$1350:$K$1364,MATCH("חג",report!$I$1350:$I$1364,0)),0) -> 3 | Q20: =IFERROR(INDEX(report!$K$1350:$K$1364,MATCH("ערב חג",report!$I$1350:$I$1364,0)),0) -> 0 | R20: =IFERROR(INDEX(report!$K$1350:$K$1364,MATCH("חול המועד",report!$I$1350:$I$1364,0)),0) -> 0 | S20: =IFERROR(INDEX(report!$K$1350:$K$1364,MATCH("תאונת עבודה",report!$I$1350:$I$1364,0)),0) -> 0 | T20: =IFERROR(INDEX(report!$K$1350:$K$1364,MATCH("חופש",report!$I$1350:$I$1364,0)),0) -> 0 | U20: =22-M20-N20-O20 -> 22 | V20: =D20-U20 -> 0
A21: 94 | B21: טל ניב | C21: =report!C1820 -> 19 | D21: =report!C1821 -> 22 | E21: =IFERROR(INDEX(report!$K$1819:$K$1833,MATCH("חופשה לחיוב",report!$I$1819:$I$1833,0)),0) -> 0 | F21: =IFERROR(INDEX(report!$K$1819:$K$1833,MATCH("מחלה",report!$I$1819:$I$1833,0)),0) -> 0 | G21: =IFERROR(INDEX(report!$K$1819:$K$1833,MATCH("מילואים",report!$I$1819:$I$1833,0)),0) -> 0 | H21: =report!G1817 -> 151.96 | I21: =report!J1817 -> 150.9 | J21: =report!K1817 -> 1.06 | K21: 0 | L21: =report!C1829 -> 0 | M21: =IFERROR(INDEX(report!$K$1819:$K$1833,MATCH("מחלה לקיזוז",report!$I$1819:$I$1833,0)),0) -> 0 | N21: =IFERROR(INDEX(report!$K$1819:$K$1833,MATCH("חל""ת",report!$I$1819:$I$1833,0)),0) -> 0 | O21: =IFERROR(INDEX(report!$K$1819:$K$1833,MATCH("היעדרות",report!$I$1819:$I$1833,0)),0) -> 0 | P21: =IFERROR(INDEX(report!$K$1819:$K$1833,MATCH("חג",report!$I$1819:$I$1833,0)),0) -> 3 | Q21: =IFERROR(INDEX(report!$K$1819:$K$1833,MATCH("ערב חג",report!$I$1819:$I$1833,0)),0) -> 0 | R21: =IFERROR(INDEX(report!$K$1819:$K$1833,MATCH("חול המועד",report!$I$1819:$I$1833,0)),0) -> 2 | S21: =IFERROR(INDEX(report!$K$1819:$K$1833,MATCH("תאונת עבודה",report!$I$1819:$I$1833,0)),0) -> 0 | T21: =IFERROR(INDEX(report!$K$1819:$K$1833,MATCH("חופש",report!$I$1819:$I$1833,0)),0) -> 0 | U21: =22-M21-N21-O21 -> 22 | V21: =D21-U21 -> 0
A22: 95 | B22: אריאל אליה | C22: =report!C253 -> 0 | D22: =report!C254 -> 22 | E22: =IFERROR(INDEX(report!$K$252:$K$266,MATCH("חופשה לחיוב",report!$I$252:$I$266,0)),0) -> 0 | F22: =IFERROR(INDEX(report!$K$252:$K$266,MATCH("מחלה",report!$I$252:$I$266,0)),0) -> 0 | G22: =IFERROR(INDEX(report!$K$252:$K$266,MATCH("מילואים",report!$I$252:$I$266,0)),0) -> 0 | H22: =report!G250 -> 0 | I22: 0 | J22: 0 | K22: 0 | L22: =report!C262 -> 0 | M22: =IFERROR(INDEX(report!$K$252:$K$266,MATCH("מחלה לקיזוז",report!$I$252:$I$266,0)),0) -> 0 | N22: =IFERROR(INDEX(report!$K$252:$K$266,MATCH("חל""ת",report!$I$252:$I$266,0)),0) -> 0 | O22: =IFERROR(INDEX(report!$K$252:$K$266,MATCH("היעדרות",report!$I$252:$I$266,0)),0) -> 0 | P22: =IFERROR(INDEX(report!$K$252:$K$266,MATCH("חג",report!$I$252:$I$266,0)),0) -> 0 | Q22: =IFERROR(INDEX(report!$K$252:$K$266,MATCH("ערב חג",report!$I$252:$I$266,0)),0) -> 0 | R22: =IFERROR(INDEX(report!$K$252:$K$266,MATCH("חול המועד",report!$I$252:$I$266,0)),0) -> 0 | S22: =IFERROR(INDEX(report!$K$252:$K$266,MATCH("תאונת עבודה",report!$I$252:$I$266,0)),0) -> 22 | T22: =IFERROR(INDEX(report!$K$252:$K$266,MATCH("חופש",report!$I$252:$I$266,0)),0) -> 0 | U22: =22-M22-N22-O22 -> 22 | V22: =D22-U22 -> 0
A23: 96 | B23: דניאל בנדרימר | C23: =report!C462 -> 0 | D23: =report!C463 -> 22 | E23: =IFERROR(INDEX(report!$K$461:$K$475,MATCH("חופשה לחיוב",report!$I$461:$I$475,0)),0) -> 2.5 | F23: =IFERROR(INDEX(report!$K$461:$K$475,MATCH("מחלה",report!$I$461:$I$475,0)),0) -> 0 | G23: =IFERROR(INDEX(report!$K$461:$K$475,MATCH("מילואים",report!$I$461:$I$475,0)),0) -> 28 | H23: =report!G459 -> 0 | I23: 0 | J23: 0 | K23: 0 | L23: =report!C471 -> 0 | M23: =IFERROR(INDEX(report!$K$461:$K$475,MATCH("מחלה לקיזוז",report!$I$461:$I$475,0)),0) -> 0 | N23: =IFERROR(INDEX(report!$K$461:$K$475,MATCH("חל""ת",report!$I$461:$I$475,0)),0) -> 0 | O23: =IFERROR(INDEX(report!$K$461:$K$475,MATCH("היעדרות",report!$I$461:$I$475,0)),0) -> 0 | P23: =IFERROR(INDEX(report!$K$461:$K$475,MATCH("חג",report!$I$461:$I$475,0)),0) -> 0 | Q23: =IFERROR(INDEX(report!$K$461:$K$475,MATCH("ערב חג",report!$I$461:$I$475,0)),0) -> 0 | R23: =IFERROR(INDEX(report!$K$461:$K$475,MATCH("חול המועד",report!$I$461:$I$475,0)),0) -> 0 | S23: =IFERROR(INDEX(report!$K$461:$K$475,MATCH("תאונת עבודה",report!$I$461:$I$475,0)),0) -> 0 | T23: =IFERROR(INDEX(report!$K$461:$K$475,MATCH("חופש",report!$I$461:$I$475,0)),0) -> 2 | U23: =22-M23-N23-O23 -> 22 | V23: =D23-U23 -> 0
A24: 97 | B24: משה בורך | C24: =report!C2084 -> 16 | D24: =report!C2085 -> 22 | E24: =IFERROR(INDEX(report!$K$2083:$K$2097,MATCH("חופשה לחיוב",report!$I$2083:$I$2097,0)),0) -> 1 | F24: =IFERROR(INDEX(report!$K$2083:$K$2097,MATCH("מחלה",report!$I$2083:$I$2097,0)),0) -> 0 | G24: =IFERROR(INDEX(report!$K$2083:$K$2097,MATCH("מילואים",report!$I$2083:$I$2097,0)),0) -> 6 | H24: =report!G2081 -> 137.43 | I24: =report!J2081 -> 127.76 | J24: =report!K2081 -> 9.06 | K24: =report!L2081 -> 0.6 | L24: =report!C2093 -> 0 | M24: =IFERROR(INDEX(report!$K$2083:$K$2097,MATCH("מחלה לקיזוז",report!$I$2083:$I$2097,0)),0) -> 0 | N24: =IFERROR(INDEX(report!$K$2083:$K$2097,MATCH("חל""ת",report!$I$2083:$I$2097,0)),0) -> 0 | O24: =IFERROR(INDEX(report!$K$2083:$K$2097,MATCH("היעדרות",report!$I$2083:$I$2097,0)),0) -> 0 | P24: =IFERROR(INDEX(report!$K$2083:$K$2097,MATCH("חג",report!$I$2083:$I$2097,0)),0) -> 3 | Q24: =IFERROR(INDEX(report!$K$2083:$K$2097,MATCH("ערב חג",report!$I$2083:$I$2097,0)),0) -> 0 | R24: =IFERROR(INDEX(report!$K$2083:$K$2097,MATCH("חול המועד",report!$I$2083:$I$2097,0)),0) -> 0 | S24: =IFERROR(INDEX(report!$K$2083:$K$2097,MATCH("תאונת עבודה",report!$I$2083:$I$2097,0)),0) -> 0 | T24: =IFERROR(INDEX(report!$K$2083:$K$2097,MATCH("חופש",report!$I$2083:$I$2097,0)),0) -> 1 | U24: =22-M24-N24-O24 -> 22 | V24: =D24-U24 -> 0
A25: 100 | B25: ולדה טריאקו | C25: =report!C985 -> 15 | D25: =report!C986 -> 22 | E25: =IFERROR(INDEX(report!$K$984:$K$998,MATCH("חופשה לחיוב",report!$I$984:$I$998,0)),0) -> 3 | F25: =IFERROR(INDEX(report!$K$984:$K$998,MATCH("מחלה",report!$I$984:$I$998,0)),0) -> 0 | G25: =IFERROR(INDEX(report!$K$984:$K$998,MATCH("מילואים",report!$I$984:$I$998,0)),0) -> 0 | H25: =report!G982 -> 120.03 | I25: =report!J982 -> 119.03 | J25: =report!K982 -> 1 | K25: 0 | L25: =report!C994 -> 0 | M25: =IFERROR(INDEX(report!$K$984:$K$998,MATCH("מחלה לקיזוז",report!$I$984:$I$998,0)),0) -> 0 | N25: =IFERROR(INDEX(report!$K$984:$K$998,MATCH("חל""ת",report!$I$984:$I$998,0)),0) -> 0 | O25: =IFERROR(INDEX(report!$K$984:$K$998,MATCH("היעדרות",report!$I$984:$I$998,0)),0) -> 0 | P25: =IFERROR(INDEX(report!$K$984:$K$998,MATCH("חג",report!$I$984:$I$998,0)),0) -> 3 | Q25: =IFERROR(INDEX(report!$K$984:$K$998,MATCH("ערב חג",report!$I$984:$I$998,0)),0) -> 2 | R25: =IFERROR(INDEX(report!$K$984:$K$998,MATCH("חול המועד",report!$I$984:$I$998,0)),0) -> 0 | S25: =IFERROR(INDEX(report!$K$984:$K$998,MATCH("תאונת עבודה",report!$I$984:$I$998,0)),0) -> 0 | T25: =IFERROR(INDEX(report!$K$984:$K$998,MATCH("חופש",report!$I$984:$I$998,0)),0) -> 2 | U25: =22-M25-N25-O25 -> 22 | V25: =D25-U25 -> 0
A26: 101 | B26: רפאל שועה | C26: =report!C723 -> 14 | D26: =report!C724 -> 22 | E26: =IFERROR(INDEX(report!$K$722:$K$736,MATCH("חופשה לחיוב",report!$I$722:$I$736,0)),0) -> 0.5 | F26: =IFERROR(INDEX(report!$K$722:$K$736,MATCH("מחלה",report!$I$722:$I$736,0)),0) -> 0 | G26: =IFERROR(INDEX(report!$K$722:$K$736,MATCH("מילואים",report!$I$722:$I$736,0)),0) -> 11 | H26: =report!G720 -> 117.4 | I26: =report!J720 -> 103.36 | J26: =report!K720 -> 12.85 | K26: =report!L720 -> 1.18 | L26: =report!C732 -> 0 | M26: =IFERROR(INDEX(report!$K$722:$K$736,MATCH("מחלה לקיזוז",report!$I$722:$I$736,0)),0) -> 0 | N26: =IFERROR(INDEX(report!$K$722:$K$736,MATCH("חל""ת",report!$I$722:$I$736,0)),0) -> 0 | O26: =IFERROR(INDEX(report!$K$722:$K$736,MATCH("היעדרות",report!$I$722:$I$736,0)),0) -> 0 | P26: =IFERROR(INDEX(report!$K$722:$K$736,MATCH("חג",report!$I$722:$I$736,0)),0) -> 3 | Q26: =IFERROR(INDEX(report!$K$722:$K$736,MATCH("ערב חג",report!$I$722:$I$736,0)),0) -> 0 | R26: =IFERROR(INDEX(report!$K$722:$K$736,MATCH("חול המועד",report!$I$722:$I$736,0)),0) -> 0 | S26: =IFERROR(INDEX(report!$K$722:$K$736,MATCH("תאונת עבודה",report!$I$722:$I$736,0)),0) -> 0 | T26: =IFERROR(INDEX(report!$K$722:$K$736,MATCH("חופש",report!$I$722:$I$736,0)),0) -> 0 | U26: =22-M26-N26-O26 -> 22 | V26: =D26-U26 -> 0
A27: 105 | B27: קומרוב ג'סיקה | C27: =report!C671 -> 16 | D27: =report!C672 -> 22 | E27: =IFERROR(INDEX(report!$K$670:$K$684,MATCH("חופשה לחיוב",report!$I$670:$I$684,0)),0) -> 1.5 | F27: =IFERROR(INDEX(report!$K$670:$K$684,MATCH("מחלה",report!$I$670:$I$684,0)),0) -> 0 | G27: =IFERROR(INDEX(report!$K$670:$K$684,MATCH("מילואים",report!$I$670:$I$684,0)),0) -> 0 | H27: =report!G668 -> 146.31 | I27: =report!J668 -> 134.4 | J27: =report!K668 -> 11.43 | K27: =report!L668 -> 0.48 | L27: =report!C680 -> 0 | M27: =IFERROR(INDEX(report!$K$670:$K$684,MATCH("מחלה לקיזוז",report!$I$670:$I$684,0)),0) -> 0 | N27: =IFERROR(INDEX(report!$K$670:$K$684,MATCH("חל""ת",report!$I$670:$I$684,0)),0) -> 0 | O27: =IFERROR(INDEX(report!$K$670:$K$684,MATCH("היעדרות",report!$I$670:$I$684,0)),0) -> 0 | P27: =IFERROR(INDEX(report!$K$670:$K$684,MATCH("חג",report!$I$670:$I$684,0)),0) -> 3 | Q27: =IFERROR(INDEX(report!$K$670:$K$684,MATCH("ערב חג",report!$I$670:$I$684,0)),0) -> 3 | R27: =IFERROR(INDEX(report!$K$670:$K$684,MATCH("חול המועד",report!$I$670:$I$684,0)),0) -> 2 | S27: =IFERROR(INDEX(report!$K$670:$K$684,MATCH("תאונת עבודה",report!$I$670:$I$684,0)),0) -> 0 | T27: =IFERROR(INDEX(report!$K$670:$K$684,MATCH("חופש",report!$I$670:$I$684,0)),0) -> 0 | U27: =22-M27-N27-O27 -> 22 | V27: =D27-U27 -> 0
A28: 106 | B28: אוראל שווקי | C28: =report!C1664 -> 14 | D28: =report!C1665 -> 20 | E28: =IFERROR(INDEX(report!$K$1663:$K$1677,MATCH("חופשה לחיוב",report!$I$1663:$I$1677,0)),0) -> 0.5 | F28: =IFERROR(INDEX(report!$K$1663:$K$1677,MATCH("מחלה",report!$I$1663:$I$1677,0)),0) -> 4 | G28: =IFERROR(INDEX(report!$K$1663:$K$1677,MATCH("מילואים",report!$I$1663:$I$1677,0)),0) -> 0 | H28: =report!G1661 -> 123.78 | I28: =report!J1661 -> 113.83 | J28: =report!K1661 -> 9.88 | K28: =report!L1661 -> 0.06 | L28: =report!C1673 -> 0 | M28: =IFERROR(INDEX(report!$K$1663:$K$1677,MATCH("מחלה לקיזוז",report!$I$1663:$I$1677,0)),0) -> 2 | N28: =IFERROR(INDEX(report!$K$1663:$K$1677,MATCH("חל""ת",report!$I$1663:$I$1677,0)),0) -> 0 | O28: =IFERROR(INDEX(report!$K$1663:$K$1677,MATCH("היעדרות",report!$I$1663:$I$1677,0)),0) -> 0 | P28: =IFERROR(INDEX(report!$K$1663:$K$1677,MATCH("חג",report!$I$1663:$I$1677,0)),0) -> 3 | Q28: =IFERROR(INDEX(report!$K$1663:$K$1677,MATCH("ערב חג",report!$I$1663:$I$1677,0)),0) -> 1 | R28: =IFERROR(INDEX(report!$K$1663:$K$1677,MATCH("חול המועד",report!$I$1663:$I$1677,0)),0) -> 0 | S28: =IFERROR(INDEX(report!$K$1663:$K$1677,MATCH("תאונת עבודה",report!$I$1663:$I$1677,0)),0) -> 0 | T28: =IFERROR(INDEX(report!$K$1663:$K$1677,MATCH("חופש",report!$I$1663:$I$1677,0)),0) -> 0 | U28: =22-M28-N28-O28 -> 20 | V28: =D28-U28 -> 0
A29: 109 | B29: נתן מזרחי | C29: =report!C2136 -> 15 | D29: =report!C2137 -> 22 | E29: =IFERROR(INDEX(report!$K$2135:$K$2149,MATCH("חופשה לחיוב",report!$I$2135:$I$2149,0)),0) -> 3 | F29: =IFERROR(INDEX(report!$K$2135:$K$2149,MATCH("מחלה",report!$I$2135:$I$2149,0)),0) -> 0 | G29: =IFERROR(INDEX(report!$K$2135:$K$2149,MATCH("מילואים",report!$I$2135:$I$2149,0)),0) -> 0 | H29: =report!G2133 -> 138.23 | I29: =report!J2133 -> 122.38 | J29: =report!K2133 -> 15.4 | K29: =report!L2133 -> 0.45 | L29: =report!C2145 -> 0 | M29: =IFERROR(INDEX(report!$K$2135:$K$2149,MATCH("מחלה לקיזוז",report!$I$2135:$I$2149,0)),0) -> 0 | N29: =IFERROR(INDEX(report!$K$2135:$K$2149,MATCH("חל""ת",report!$I$2135:$I$2149,0)),0) -> 0 | O29: =IFERROR(INDEX(report!$K$2135:$K$2149,MATCH("היעדרות",report!$I$2135:$I$2149,0)),0) -> 0 | P29: =IFERROR(INDEX(report!$K$2135:$K$2149,MATCH("חג",report!$I$2135:$I$2149,0)),0) -> 3 | Q29: =IFERROR(INDEX(report!$K$2135:$K$2149,MATCH("ערב חג",report!$I$2135:$I$2149,0)),0) -> 2 | R29: =IFERROR(INDEX(report!$K$2135:$K$2149,MATCH("חול המועד",report!$I$2135:$I$2149,0)),0) -> 2 | S29: =IFERROR(INDEX(report!$K$2135:$K$2149,MATCH("תאונת עבודה",report!$I$2135:$I$2149,0)),0) -> 0 | T29: =IFERROR(INDEX(report!$K$2135:$K$2149,MATCH("חופש",report!$I$2135:$I$2149,0)),0) -> 0 | U29: =22-M29-N29-O29 -> 22 | V29: =D29-U29 -> 0
A30: 110 | B30: בר אשטון | C30: =report!C305 -> 15 | D30: =report!C306 -> 22 | E30: =IFERROR(INDEX(report!$K$304:$K$318,MATCH("חופשה לחיוב",report!$I$304:$I$318,0)),0) -> 2.5 | F30: =IFERROR(INDEX(report!$K$304:$K$318,MATCH("מחלה",report!$I$304:$I$318,0)),0) -> 0 | G30: =IFERROR(INDEX(report!$K$304:$K$318,MATCH("מילואים",report!$I$304:$I$318,0)),0) -> 0 | H30: =report!G302 -> 133.73 | I30: =report!J302 -> 122.05 | J30: =report!K302 -> 10.95 | K30: =report!L302 -> 0.73 | L30: =report!C314 -> 0 | M30: =IFERROR(INDEX(report!$K$304:$K$318,MATCH("מחלה לקיזוז",report!$I$304:$I$318,0)),0) -> 0 | N30: =IFERROR(INDEX(report!$K$304:$K$318,MATCH("חל""ת",report!$I$304:$I$318,0)),0) -> 0 | O30: =IFERROR(INDEX(report!$K$304:$K$318,MATCH("היעדרות",report!$I$304:$I$318,0)),0) -> 0 | P30: =IFERROR(INDEX(report!$K$304:$K$318,MATCH("חג",report!$I$304:$I$318,0)),0) -> 3 | Q30: =IFERROR(INDEX(report!$K$304:$K$318,MATCH("ערב חג",report!$I$304:$I$318,0)),0) -> 3 | R30: =IFERROR(INDEX(report!$K$304:$K$318,MATCH("חול המועד",report!$I$304:$I$318,0)),0) -> 2 | S30: =IFERROR(INDEX(report!$K$304:$K$318,MATCH("תאונת עבודה",report!$I$304:$I$318,0)),0) -> 0 | T30: =IFERROR(INDEX(report!$K$304:$K$318,MATCH("חופש",report!$I$304:$I$318,0)),0) -> 1 | U30: =22-M30-N30-O30 -> 22 | V30: =D30-U30 -> 0
A31: 112 | B31: נהיראל כהן | C31: =report!C619 -> 4 | D31: =report!C620 -> 22 | E31: =IFERROR(INDEX(report!$K$618:$K$632,MATCH("חופשה לחיוב",report!$I$618:$I$632,0)),0) -> 2.5 | F31: =IFERROR(INDEX(report!$K$618:$K$632,MATCH("מחלה",report!$I$618:$I$632,0)),0) -> 0 | G31: =IFERROR(INDEX(report!$K$618:$K$632,MATCH("מילואים",report!$I$618:$I$632,0)),0) -> 16 | H31: =report!G616 -> 29.63 | I31: =report!J616 -> 27.11 | J31: =report!K616 -> 2.51 | K31: 0 | L31: =report!C628 -> 1.9166667 | M31: =IFERROR(INDEX(report!$K$618:$K$632,MATCH("מחלה לקיזוז",report!$I$618:$I$632,0)),0) -> 0 | N31: =IFERROR(INDEX(report!$K$618:$K$632,MATCH("חל""ת",report!$I$618:$I$632,0)),0) -> 0 | O31: =IFERROR(INDEX(report!$K$618:$K$632,MATCH("היעדרות",report!$I$618:$I$632,0)),0) -> 0 | P31: =IFERROR(INDEX(report!$K$618:$K$632,MATCH("חג",report!$I$618:$I$632,0)),0) -> 3 | Q31: =IFERROR(INDEX(report!$K$618:$K$632,MATCH("ערב חג",report!$I$618:$I$632,0)),0) -> 3 | R31: =IFERROR(INDEX(report!$K$618:$K$632,MATCH("חול המועד",report!$I$618:$I$632,0)),0) -> 2 | S31: =IFERROR(INDEX(report!$K$618:$K$632,MATCH("תאונת עבודה",report!$I$618:$I$632,0)),0) -> 0 | T31: =IFERROR(INDEX(report!$K$618:$K$632,MATCH("חופש",report!$I$618:$I$632,0)),0) -> 1 | U31: =22-M31-N31-O31 -> 22 | V31: =D31-U31 -> 0
A32: 113 | B32: אורי אשתר | C32: =report!C43 -> 14 | D32: =report!C44 -> 22 | E32: =IFERROR(INDEX(report!$K$42:$K$56,MATCH("חופשה לחיוב",report!$I$42:$I$56,0)),0) -> 3.5 | F32: =IFERROR(INDEX(report!$K$42:$K$56,MATCH("מחלה",report!$I$42:$I$56,0)),0) -> 0 | G32: =IFERROR(INDEX(report!$K$42:$K$56,MATCH("מילואים",report!$I$42:$I$56,0)),0) -> 0 | H32: =report!G40 -> 117.25 | I32: =report!J40 -> 114.51 | J32: =report!K40 -> 2.73 | K32: 0 | L32: =report!C52 -> 0 | M32: =IFERROR(INDEX(report!$K$42:$K$56,MATCH("מחלה לקיזוז",report!$I$42:$I$56,0)),0) -> 0 | N32: =IFERROR(INDEX(report!$K$42:$K$56,MATCH("חל""ת",report!$I$42:$I$56,0)),0) -> 0 | O32: =IFERROR(INDEX(report!$K$42:$K$56,MATCH("היעדרות",report!$I$42:$I$56,0)),0) -> 0 | P32: =IFERROR(INDEX(report!$K$42:$K$56,MATCH("חג",report!$I$42:$I$56,0)),0) -> 3 | Q32: =IFERROR(INDEX(report!$K$42:$K$56,MATCH("ערב חג",report!$I$42:$I$56,0)),0) -> 3 | R32: =IFERROR(INDEX(report!$K$42:$K$56,MATCH("חול המועד",report!$I$42:$I$56,0)),0) -> 2 | S32: =IFERROR(INDEX(report!$K$42:$K$56,MATCH("תאונת עבודה",report!$I$42:$I$56,0)),0) -> 0 | T32: =IFERROR(INDEX(report!$K$42:$K$56,MATCH("חופש",report!$I$42:$I$56,0)),0) -> 0 | U32: =22-M32-N32-O32 -> 22 | V32: =D32-U32 -> 0
A33: 115 | B33: יענקל מונטבולינסקי | C33: =report!C1872 -> 16 | D33: =report!C1873 -> 21 | E33: =IFERROR(INDEX(report!$K$1871:$K$1885,MATCH("חופשה לחיוב",report!$I$1871:$I$1885,0)),0) -> 1 | F33: =IFERROR(INDEX(report!$K$1871:$K$1885,MATCH("מחלה",report!$I$1871:$I$1885,0)),0) -> 1 | G33: =IFERROR(INDEX(report!$K$1871:$K$1885,MATCH("מילואים",report!$I$1871:$I$1885,0)),0) -> 0 | H33: =report!G1869 -> 127.2 | I33: =report!J1869 -> 124.03 | J33: =report!K1869 -> 3.16 | K33: 0 | L33: =report!C1881 -> 0 | M33: =IFERROR(INDEX(report!$K$1871:$K$1885,MATCH("מחלה לקיזוז",report!$I$1871:$I$1885,0)),0) -> 1 | N33: =IFERROR(INDEX(report!$K$1871:$K$1885,MATCH("חל""ת",report!$I$1871:$I$1885,0)),0) -> 0 | O33: =IFERROR(INDEX(report!$K$1871:$K$1885,MATCH("היעדרות",report!$I$1871:$I$1885,0)),0) -> 0 | P33: =IFERROR(INDEX(report!$K$1871:$K$1885,MATCH("חג",report!$I$1871:$I$1885,0)),0) -> 3 | Q33: =IFERROR(INDEX(report!$K$1871:$K$1885,MATCH("ערב חג",report!$I$1871:$I$1885,0)),0) -> 2 | R33: =IFERROR(INDEX(report!$K$1871:$K$1885,MATCH("חול המועד",report!$I$1871:$I$1885,0)),0) -> 0 | S33: =IFERROR(INDEX(report!$K$1871:$K$1885,MATCH("תאונת עבודה",report!$I$1871:$I$1885,0)),0) -> 0 | T33: =IFERROR(INDEX(report!$K$1871:$K$1885,MATCH("חופש",report!$I$1871:$I$1885,0)),0) -> 0 | U33: =22-M33-N33-O33 -> 21 | V33: =D33-U33 -> 0
A34: 116 | B34: אבישי שרון מהדקאר | C34: =report!C2240 -> 16 | D34: =report!C2241 -> 22 | E34: =IFERROR(INDEX(report!$K$2239:$K$2253,MATCH("חופשה לחיוב",report!$I$2239:$I$2253,0)),0) -> 3 | F34: =IFERROR(INDEX(report!$K$2239:$K$2253,MATCH("מחלה",report!$I$2239:$I$2253,0)),0) -> 0 | G34: =IFERROR(INDEX(report!$K$2239:$K$2253,MATCH("מילואים",report!$I$2239:$I$2253,0)),0) -> 0 | H34: =report!G2237 -> 152.38 | I34: =report!J2237 -> 107.8 | J34: =report!K2237 -> 16.7 | K34: =report!L2237 -> 27.88 | L34: =report!C2249 -> 0 | M34: =IFERROR(INDEX(report!$K$2239:$K$2253,MATCH("מחלה לקיזוז",report!$I$2239:$I$2253,0)),0) -> 0 | N34: =IFERROR(INDEX(report!$K$2239:$K$2253,MATCH("חל""ת",report!$I$2239:$I$2253,0)),0) -> 0 | O34: =IFERROR(INDEX(report!$K$2239:$K$2253,MATCH("היעדרות",report!$I$2239:$I$2253,0)),0) -> 0 | P34: =IFERROR(INDEX(report!$K$2239:$K$2253,MATCH("חג",report!$I$2239:$I$2253,0)),0) -> 3 | Q34: =IFERROR(INDEX(report!$K$2239:$K$2253,MATCH("ערב חג",report!$I$2239:$I$2253,0)),0) -> 2 | R34: =IFERROR(INDEX(report!$K$2239:$K$2253,MATCH("חול המועד",report!$I$2239:$I$2253,0)),0) -> 2 | S34: =IFERROR(INDEX(report!$K$2239:$K$2253,MATCH("תאונת עבודה",report!$I$2239:$I$2253,0)),0) -> 0 | T34: =IFERROR(INDEX(report!$K$2239:$K$2253,MATCH("חופש",report!$I$2239:$I$2253,0)),0) -> 0 | U34: =22-M34-N34-O34 -> 22 | V34: =D34-U34 -> 0
A35: 117 | B35: הודיה הכהן | C35: =report!C1246 -> 12 | D35: =report!C1247 -> 21 | E35: =IFERROR(INDEX(report!$K$1245:$K$1259,MATCH("חופשה לחיוב",report!$I$1245:$I$1259,0)),0) -> 4.5 | F35: =IFERROR(INDEX(report!$K$1245:$K$1259,MATCH("מחלה",report!$I$1245:$I$1259,0)),0) -> 0 | G35: =IFERROR(INDEX(report!$K$1245:$K$1259,MATCH("מילואים",report!$I$1245:$I$1259,0)),0) -> 0 | H35: =report!G1243 -> 116.65 | I35: =report!J1243 -> 99.5 | J35: =report!K1243 -> 14.21 | K35: =report!L1243 -> 2.93 | L35: =report!C1255 -> 0 | M35: =IFERROR(INDEX(report!$K$1245:$K$1259,MATCH("מחלה לקיזוז",report!$I$1245:$I$1259,0)),0) -> 0 | N35: =IFERROR(INDEX(report!$K$1245:$K$1259,MATCH("חל""ת",report!$I$1245:$I$1259,0)),0) -> 0 | O35: =IFERROR(INDEX(report!$K$1245:$K$1259,MATCH("היעדרות",report!$I$1245:$I$1259,0)),0) -> 0 | P35: =IFERROR(INDEX(report!$K$1245:$K$1259,MATCH("חג",report!$I$1245:$I$1259,0)),0) -> 3 | Q35: =IFERROR(INDEX(report!$K$1245:$K$1259,MATCH("ערב חג",report!$I$1245:$I$1259,0)),0) -> 3 | R35: =IFERROR(INDEX(report!$K$1245:$K$1259,MATCH("חול המועד",report!$I$1245:$I$1259,0)),0) -> 2 | S35: =IFERROR(INDEX(report!$K$1245:$K$1259,MATCH("תאונת עבודה",report!$I$1245:$I$1259,0)),0) -> 0 | T35: =IFERROR(INDEX(report!$K$1245:$K$1259,MATCH("חופש",report!$I$1245:$I$1259,0)),0) -> 1 | U35: =22-M35-N35-O35 -> 22 | V35: =D35-U35 -> -1
A36: 118 | B36: אורי דוד עברי | C36: =report!C96 -> 12 | D36: =report!C97 -> 20 | E36: =IFERROR(INDEX(report!$K$95:$K$109,MATCH("חופשה לחיוב",report!$I$95:$I$109,0)),0) -> 0 | F36: =IFERROR(INDEX(report!$K$95:$K$109,MATCH("מחלה",report!$I$95:$I$109,0)),0) -> 0 | G36: =IFERROR(INDEX(report!$K$95:$K$109,MATCH("מילואים",report!$I$95:$I$109,0)),0) -> 3 | H36: =report!G93 -> 79 | I36: =report!J93 -> 77.81 | J36: =report!K93 -> 1.18 | K36: 0 | L36: =report!C105 -> 3.0833333 | M36: =IFERROR(INDEX(report!$K$95:$K$109,MATCH("מחלה לקיזוז",report!$I$95:$I$109,0)),0) -> 0 | N36: =IFERROR(INDEX(report!$K$95:$K$109,MATCH("חל""ת",report!$I$95:$I$109,0)),0) -> 0 | O36: =IFERROR(INDEX(report!$K$95:$K$109,MATCH("היעדרות",report!$I$95:$I$109,0)),0) -> 0 | P36: =IFERROR(INDEX(report!$K$95:$K$109,MATCH("חג",report!$I$95:$I$109,0)),0) -> 3 | Q36: =IFERROR(INDEX(report!$K$95:$K$109,MATCH("ערב חג",report!$I$95:$I$109,0)),0) -> 2 | R36: =IFERROR(INDEX(report!$K$95:$K$109,MATCH("חול המועד",report!$I$95:$I$109,0)),0) -> 2 | S36: =IFERROR(INDEX(report!$K$95:$K$109,MATCH("תאונת עבודה",report!$I$95:$I$109,0)),0) -> 0 | T36: =IFERROR(INDEX(report!$K$95:$K$109,MATCH("חופש",report!$I$95:$I$109,0)),0) -> 1 | U36: =22-M36-N36-O36 -> 22 | V36: =D36-U36 -> -2
A37: 119 | B37: טל בירנבאום | C37: =report!C1299 -> 12 | D37: =report!C1300 -> 11 | E37: =IFERROR(INDEX(report!$K$1298:$K$1312,MATCH("חופשה לחיוב",report!$I$1298:$I$1312,0)),0) -> 2.5 | F37: =IFERROR(INDEX(report!$K$1298:$K$1312,MATCH("מחלה",report!$I$1298:$I$1312,0)),0) -> 0 | G37: =IFERROR(INDEX(report!$K$1298:$K$1312,MATCH("מילואים",report!$I$1298:$I$1312,0)),0) -> 0 | H37: =report!G1296 -> 83.11 | I37: =report!J1296 -> 82.96 | J37: =report!K1296 -> 0.15 | K37: 0 | L37: =report!C1308 -> 0 | M37: =IFERROR(INDEX(report!$K$1298:$K$1312,MATCH("מחלה לקיזוז",report!$I$1298:$I$1312,0)),0) -> 0 | N37: =IFERROR(INDEX(report!$K$1298:$K$1312,MATCH("חל""ת",report!$I$1298:$I$1312,0)),0) -> 11 | O37: =IFERROR(INDEX(report!$K$1298:$K$1312,MATCH("היעדרות",report!$I$1298:$I$1312,0)),0) -> 0 | P37: =IFERROR(INDEX(report!$K$1298:$K$1312,MATCH("חג",report!$I$1298:$I$1312,0)),0) -> 3 | Q37: =IFERROR(INDEX(report!$K$1298:$K$1312,MATCH("ערב חג",report!$I$1298:$I$1312,0)),0) -> 3 | R37: =IFERROR(INDEX(report!$K$1298:$K$1312,MATCH("חול המועד",report!$I$1298:$I$1312,0)),0) -> 0 | S37: =IFERROR(INDEX(report!$K$1298:$K$1312,MATCH("תאונת עבודה",report!$I$1298:$I$1312,0)),0) -> 0 | T37: =IFERROR(INDEX(report!$K$1298:$K$1312,MATCH("חופש",report!$I$1298:$I$1312,0)),0) -> 1 | U37: =22-M37-N37-O37 -> 11 | V37: =D37-U37 -> 0
A38: 121 | B38: איתי קעטבי | C38: =report!C148 -> 5 | D38: =report!C149 -> 22 | E38: =IFERROR(INDEX(report!$K$147:$K$161,MATCH("חופשה לחיוב",report!$I$147:$I$161,0)),0) -> 3.5 | F38: =IFERROR(INDEX(report!$K$147:$K$161,MATCH("מחלה",report!$I$147:$I$161,0)),0) -> 0 | G38: =IFERROR(INDEX(report!$K$147:$K$161,MATCH("מילואים",report!$I$147:$I$161,0)),0) -> 9 | H38: =report!G145 -> 45.96 | I38: =report!J145 -> 42 | J38: =report!K145 -> 3.86 | K38: =report!L145 -> 0.1 | L38: =report!C157 -> 0 | M38: =IFERROR(INDEX(report!$K$147:$K$161,MATCH("מחלה לקיזוז",report!$I$147:$I$161,0)),0) -> 0 | N38: =IFERROR(INDEX(report!$K$147:$K$161,MATCH("חל""ת",report!$I$147:$I$161,0)),0) -> 0 | O38: =IFERROR(INDEX(report!$K$147:$K$161,MATCH("היעדרות",report!$I$147:$I$161,0)),0) -> 0 | P38: =IFERROR(INDEX(report!$K$147:$K$161,MATCH("חג",report!$I$147:$I$161,0)),0) -> 3 | Q38: =IFERROR(INDEX(report!$K$147:$K$161,MATCH("ערב חג",report!$I$147:$I$161,0)),0) -> 3 | R38: =IFERROR(INDEX(report!$K$147:$K$161,MATCH("חול המועד",report!$I$147:$I$161,0)),0) -> 2 | S38: =IFERROR(INDEX(report!$K$147:$K$161,MATCH("תאונת עבודה",report!$I$147:$I$161,0)),0) -> 0 | T38: =IFERROR(INDEX(report!$K$147:$K$161,MATCH("חופש",report!$I$147:$I$161,0)),0) -> 0 | U38: =22-M38-N38-O38 -> 22 | V38: =D38-U38 -> 0
A39: 122 | B39: Tami demello | C39: =report!C879 -> 8 | D39: =report!C880 -> 22 | E39: =IFERROR(INDEX(report!$K$878:$K$892,MATCH("חופשה לחיוב",report!$I$878:$I$892,0)),0) -> 3.5 | F39: =IFERROR(INDEX(report!$K$878:$K$892,MATCH("מחלה",report!$I$878:$I$892,0)),0) -> 0 | G39: =IFERROR(INDEX(report!$K$878:$K$892,MATCH("מילואים",report!$I$878:$I$892,0)),0) -> 0 | H39: =report!G876 -> 23.91 | I39: =report!J876 -> 23.08 | J39: =report!K876 -> 0.83 | K39: 0 | L39: =report!C888 -> 0 | M39: =IFERROR(INDEX(report!$K$878:$K$892,MATCH("מחלה לקיזוז",report!$I$878:$I$892,0)),0) -> 0 | N39: =IFERROR(INDEX(report!$K$878:$K$892,MATCH("חל""ת",report!$I$878:$I$892,0)),0) -> 0 | O39: =IFERROR(INDEX(report!$K$878:$K$892,MATCH("היעדרות",report!$I$878:$I$892,0)),0) -> 0 | P39: =IFERROR(INDEX(report!$K$878:$K$892,MATCH("חג",report!$I$878:$I$892,0)),0) -> 3 | Q39: =IFERROR(INDEX(report!$K$878:$K$892,MATCH("ערב חג",report!$I$878:$I$892,0)),0) -> 3 | R39: =IFERROR(INDEX(report!$K$878:$K$892,MATCH("חול המועד",report!$I$878:$I$892,0)),0) -> 2 | S39: =IFERROR(INDEX(report!$K$878:$K$892,MATCH("תאונת עבודה",report!$I$878:$I$892,0)),0) -> 0 | T39: =IFERROR(INDEX(report!$K$878:$K$892,MATCH("חופש",report!$I$878:$I$892,0)),0) -> 0 | U39: =22-M39-N39-O39 -> 22 | V39: =D39-U39 -> 0
A40: 123 | B40: אריק רוזנווסר | C40: =report!C1768 -> 13 | D40: =report!C1769 -> 20 | E40: =IFERROR(INDEX(report!$K$1767:$K$1781,MATCH("חופשה לחיוב",report!$I$1767:$I$1781,0)),0) -> 3 | F40: =IFERROR(INDEX(report!$K$1767:$K$1781,MATCH("מחלה",report!$I$1767:$I$1781,0)),0) -> 0 | G40: =IFERROR(INDEX(report!$K$1767:$K$1781,MATCH("מילואים",report!$I$1767:$I$1781,0)),0) -> 0 | H40: =report!G1765 -> 107.96 | I40: =report!J1765 -> 106.25 | J40: =report!K1765 -> 1.71 | K40: 0 | L40: =report!C1777 -> 0 | M40: =IFERROR(INDEX(report!$K$1767:$K$1781,MATCH("מחלה לקיזוז",report!$I$1767:$I$1781,0)),0) -> 0 | N40: =IFERROR(INDEX(report!$K$1767:$K$1781,MATCH("חל""ת",report!$I$1767:$I$1781,0)),0) -> 0 | O40: =IFERROR(INDEX(report!$K$1767:$K$1781,MATCH("היעדרות",report!$I$1767:$I$1781,0)),0) -> 0 | P40: =IFERROR(INDEX(report!$K$1767:$K$1781,MATCH("חג",report!$I$1767:$I$1781,0)),0) -> 3 | Q40: =IFERROR(INDEX(report!$K$1767:$K$1781,MATCH("ערב חג",report!$I$1767:$I$1781,0)),0) -> 2 | R40: =IFERROR(INDEX(report!$K$1767:$K$1781,MATCH("חול המועד",report!$I$1767:$I$1781,0)),0) -> 2 | S40: =IFERROR(INDEX(report!$K$1767:$K$1781,MATCH("תאונת עבודה",report!$I$1767:$I$1781,0)),0) -> 0 | T40: =IFERROR(INDEX(report!$K$1767:$K$1781,MATCH("חופש",report!$I$1767:$I$1781,0)),0) -> 0 | U40: =22-M40-N40-O40 -> 22 | V40: =D40-U40 -> -2
A41: 124 | B41: מיכה אברג'ל | C41: =report!C1456 -> 8 | D41: =report!C1457 -> 22 | E41: =IFERROR(INDEX(report!$K$1455:$K$1469,MATCH("חופשה לחיוב",report!$I$1455:$I$1469,0)),0) -> 2.5 | F41: =IFERROR(INDEX(report!$K$1455:$K$1469,MATCH("מחלה",report!$I$1455:$I$1469,0)),0) -> 0 | G41: =IFERROR(INDEX(report!$K$1455:$K$1469,MATCH("מילואים",report!$I$1455:$I$1469,0)),0) -> 12 | H41: =report!G1453 -> 55.63 | I41: =report!J1453 -> 54.86 | J41: =report!K1453 -> 0.76 | K41: 0 | L41: =report!C1465 -> 0 | M41: =IFERROR(INDEX(report!$K$1455:$K$1469,MATCH("מחלה לקיזוז",report!$I$1455:$I$1469,0)),0) -> 0 | N41: =IFERROR(INDEX(report!$K$1455:$K$1469,MATCH("חל""ת",report!$I$1455:$I$1469,0)),0) -> 0 | O41: =IFERROR(INDEX(report!$K$1455:$K$1469,MATCH("היעדרות",report!$I$1455:$I$1469,0)),0) -> 0 | P41: =IFERROR(INDEX(report!$K$1455:$K$1469,MATCH("חג",report!$I$1455:$I$1469,0)),0) -> 3 | Q41: =IFERROR(INDEX(report!$K$1455:$K$1469,MATCH("ערב חג",report!$I$1455:$I$1469,0)),0) -> 3 | R41: =IFERROR(INDEX(report!$K$1455:$K$1469,MATCH("חול המועד",report!$I$1455:$I$1469,0)),0) -> 2 | S41: =IFERROR(INDEX(report!$K$1455:$K$1469,MATCH("תאונת עבודה",report!$I$1455:$I$1469,0)),0) -> 0 | T41: =IFERROR(INDEX(report!$K$1455:$K$1469,MATCH("חופש",report!$I$1455:$I$1469,0)),0) -> 1 | U41: =22-M41-N41-O41 -> 22 | V41: =D41-U41 -> 0
...

Sheet 1.סיכום ימים
A1: 1. סיכום ימים - דינמי (נוסחאות מ-report)
A3: מס' עובד | B3: שם עובד | C3: ימי נוכחות | D3: חופש קיים | E3: חופשה לחיוב | F3: סה"כ חופשה | G3: מילואים | H3: תאונת עבודה | I3: ימי מחלה | J3: מחלה לקיזוז | K3: חג | L3: ערב חג | M3: חוה"מ | N3: ימים משולמים | O3: סטטוס | P3: הערה | Q3: חל"ת | R3: היעדרות
A4: 2 | B4: אבישי לייבנזון | C4: =report!C931 -> 0 | D4: =IFERROR(INDEX(report!$K$930:$K$944,MATCH("חופש",report!$I$930:$I$944,0)),0) -> 0 | E4: =IFERROR(INDEX(report!$K$930:$K$944,MATCH("חופשה לחיוב",report!$I$930:$I$944,0)),0) -> 3.5 | F4: =E4 -> 3.5 | G4: =IFERROR(INDEX(report!$K$930:$K$944,MATCH("מילואים",report!$I$930:$I$944,0)),0) -> 0 | H4: =IFERROR(INDEX(report!$K$930:$K$944,MATCH("תאונת עבודה",report!$I$930:$I$944,0)),0) -> 0 | I4: =IFERROR(INDEX(report!$K$930:$K$944,MATCH("מחלה",report!$I$930:$I$944,0)),0) -> 0 | J4: =IFERROR(INDEX(report!$K$930:$K$944,MATCH("מחלה לקיזוז",report!$I$930:$I$944,0)),0) -> 0 | K4: =IFERROR(INDEX(report!$K$930:$K$944,MATCH("חג",report!$I$930:$I$944,0)),0) -> 3 | L4: =IFERROR(INDEX(report!$K$930:$K$944,MATCH("ערב חג",report!$I$930:$I$944,0)),0) -> 3 | M4: =IFERROR(INDEX(report!$K$930:$K$944,MATCH("חול המועד",report!$I$930:$I$944,0)),0) -> 2 | N4: =report!C932 -> 22 | O4: ✓ | Q4: =IFERROR(INDEX(report!$K$930:$K$944,MATCH("חל""ת",report!$I$930:$I$944,0)),0) -> 0 | R4: =IFERROR(INDEX(report!$K$930:$K$944,MATCH("היעדרות",report!$I$930:$I$944,0)),0) -> 0
A5: 7 | B5: חיים ראש | C5: =report!C514 -> 12 | D5: =IFERROR(INDEX(report!$K$513:$K$527,MATCH("חופש",report!$I$513:$I$527,0)),0) -> 2 | E5: =IFERROR(INDEX(report!$K$513:$K$527,MATCH("חופשה לחיוב",report!$I$513:$I$527,0)),0) -> 4.5 | F5: =E5 -> 4.5 | G5: =IFERROR(INDEX(report!$K$513:$K$527,MATCH("מילואים",report!$I$513:$I$527,0)),0) -> 0 | H5: =IFERROR(INDEX(report!$K$513:$K$527,MATCH("תאונת עבודה",report!$I$513:$I$527,0)),0) -> 0 | I5: =IFERROR(INDEX(report!$K$513:$K$527,MATCH("מחלה",report!$I$513:$I$527,0)),0) -> 0 | J5: =IFERROR(INDEX(report!$K$513:$K$527,MATCH("מחלה לקיזוז",report!$I$513:$I$527,0)),0) -> 0 | K5: =IFERROR(INDEX(report!$K$513:$K$527,MATCH("חג",report!$I$513:$I$527,0)),0) -> 3 | L5: =IFERROR(INDEX(report!$K$513:$K$527,MATCH("ערב חג",report!$I$513:$I$527,0)),0) -> 3 | M5: =IFERROR(INDEX(report!$K$513:$K$527,MATCH("חול המועד",report!$I$513:$I$527,0)),0) -> 2 | N5: =report!C515 -> 21 | O5: ✓ | Q5: =IFERROR(INDEX(report!$K$513:$K$527,MATCH("חל""ת",report!$I$513:$I$527,0)),0) -> 0 | R5: =IFERROR(INDEX(report!$K$513:$K$527,MATCH("היעדרות",report!$I$513:$I$527,0)),0) -> 0
A6: 8 | B6: דוד אחדות | C6: =report!C358 -> 12 | D6: =IFERROR(INDEX(report!$K$357:$K$371,MATCH("חופש",report!$I$357:$I$371,0)),0) -> 2 | E6: =IFERROR(INDEX(report!$K$357:$K$371,MATCH("חופשה לחיוב",report!$I$357:$I$371,0)),0) -> 5.5 | F6: =E6 -> 5.5 | G6: =IFERROR(INDEX(report!$K$357:$K$371,MATCH("מילואים",report!$I$357:$I$371,0)),0) -> 0 | H6: =IFERROR(INDEX(report!$K$357:$K$371,MATCH("תאונת עבודה",report!$I$357:$I$371,0)),0) -> 0 | I6: =IFERROR(INDEX(report!$K$357:$K$371,MATCH("מחלה",report!$I$357:$I$371,0)),0) -> 0 | J6: =IFERROR(INDEX(report!$K$357:$K$371,MATCH("מחלה לקיזוז",report!$I$357:$I$371,0)),0) -> 0 | K6: =IFERROR(INDEX(report!$K$357:$K$371,MATCH("חג",report!$I$357:$I$371,0)),0) -> 3 | L6: =IFERROR(INDEX(report!$K$357:$K$371,MATCH("ערב חג",report!$I$357:$I$371,0)),0) -> 3 | M6: =IFERROR(INDEX(report!$K$357:$K$371,MATCH("חול המועד",report!$I$357:$I$371,0)),0) -> 2 | N6: =report!C359 -> 22 | O6: ✓ | Q6: =IFERROR(INDEX(report!$K$357:$K$371,MATCH("חל""ת",report!$I$357:$I$371,0)),0) -> 0 | R6: =IFERROR(INDEX(report!$K$357:$K$371,MATCH("היעדרות",report!$I$357:$I$371,0)),0) -> 0
A7: 11 | B7: לוי דביש | C7: =report!C566 -> 12 | D7: =IFERROR(INDEX(report!$K$565:$K$579,MATCH("חופש",report!$I$565:$I$579,0)),0) -> 0 | E7: =IFERROR(INDEX(report!$K$565:$K$579,MATCH("חופשה לחיוב",report!$I$565:$I$579,0)),0) -> 1.5 | F7: =E7 -> 1.5 | G7: =IFERROR(INDEX(report!$K$565:$K$579,MATCH("מילואים",report!$I$565:$I$579,0)),0) -> 0 | H7: =IFERROR(INDEX(report!$K$565:$K$579,MATCH("תאונת עבודה",report!$I$565:$I$579,0)),0) -> 0 | I7: =IFERROR(INDEX(report!$K$565:$K$579,MATCH("מחלה",report!$I$565:$I$579,0)),0) -> 0 | J7: =IFERROR(INDEX(report!$K$565:$K$579,MATCH("מחלה לקיזוז",report!$I$565:$I$579,0)),0) -> 0 | K7: =IFERROR(INDEX(report!$K$565:$K$579,MATCH("חג",report!$I$565:$I$579,0)),0) -> 3 | L7: =IFERROR(INDEX(report!$K$565:$K$579,MATCH("ערב חג",report!$I$565:$I$579,0)),0) -> 3 | M7: =IFERROR(INDEX(report!$K$565:$K$579,MATCH("חול המועד",report!$I$565:$I$579,0)),0) -> 2 | N7: =report!C567 -> 20 | O7: ✓ | Q7: =IFERROR(INDEX(report!$K$565:$K$579,MATCH("חל""ת",report!$I$565:$I$579,0)),0) -> 0 | R7: =IFERROR(INDEX(report!$K$565:$K$579,MATCH("היעדרות",report!$I$565:$I$579,0)),0) -> 2
